Workbook
Name FuelDensity: 'Fuel Properties'!$C$8

Sheet Fuel Properties
B3: Fuel Density (kg/m^3) | C3: 785.594
B4: M1 Co-efficient (kg/m^3/C) | C4: 0.8104
B6: Calculator
B7: Temperature | C7: 20
B8: Fuel Density | C8: =C3+C4*(25-C7) -> 789.646
B12: Stoichiometric ratio for the e85 as 9.386.
B13: Molar mass of the e85 as 50.410
B14: The estimated Volumetric Coefficient of Thermal Expansion (1/K) as 0.00107
B15: M1 Coeff[TE] as 0.8104 kg/m^3 / deg C
B16: Density at 25 deg C as 785.594 kg/m^3

Sheet Fuel Consumption P1
B2: Fuel Consumption - 04 RUA
AC3: GM | AD3: Ford | AE3: Toyota
C4: GM | D4: Ford | E4: Toyota | G4: Make | H4: Cars | I4: Driver | J4: Laps | K4: Fuel Used EOL Average [l] | AB4: Lap 1 | AC4: =$C$5 -> 2.9371875 | AD4: =$D$5 -> 3.0040172 | AE4: =$E$5 -> 3.0314683
B5: Av Fuel Used | C5: {=_xlfn.LET(_xlpm.data, $G$5:$K$10, _xlpm.filtered, _xlfn._xlws.FILTER(_xlpm.data, $G$5:$G$10='Fuel Consumption P1'!C4), _xlpm.EOL, _xlfn.CHOOSECOLS(_xlpm.filtered,5), AVERAGE(_xlpm.EOL))} -> 2.9371875 | D5: {=_xlfn.LET(_xlpm.data, $G$5:$K$10, _xlpm.filtered, _xlfn._xlws.FILTER(_xlpm.data, $G$5:$G$10='Fuel Consumption P1'!D4), _xlpm.EOL, _xlfn.CHOOSECOLS(_xlpm.filtered,5), AVERAGE(_xlpm.EOL))} -> 3.0040172 | E5: {=_xlfn.LET(_xlpm.data, $G$5:$K$10, _xlpm.filtered, _xlfn._xlws.FILTER(_xlpm.data, $G$5:$G$10='Fuel Consumption P1'!E4), _xlpm.EOL, _xlfn.CHOOSECOLS(_xlpm.filtered,5), AVERAGE(_xlpm.EOL))} -> 3.0314683 | G5: Toyota | H5: 8 | I5: Andre Heimgartner, BJR019 | J5: 6 | K5: {=_xlfn.LET(_xlpm.data, 'DUMP P1'!$A$3:$H$10000, _xlpm.filtered, _xlfn._xlws.FILTER(_xlpm.data,'DUMP P1'!$B$3:$B$10000='Fuel Consumption P1'!I5), _xlpm.EOL, _xlfn.CHOOSECOLS(_xlpm.filtered,7), _xlpm.Error, _xlfn.CHOOSECOLS(_xlpm.filtered,8), AVERAGE(_xlpm.Error*_xlpm.EOL))} -> 3.0429067 | AB5: Lap 2 | AC5: =$C$5 -> 2.9371875 | AD5: =$D$5 -> 3.0040172 | AE5: =$E$5 -> 3.0314683
G6: Toyota | H6: 96 | I6: Macauley Jones, BJR018 | J6: 5 | K6: {=_xlfn.LET(_xlpm.data, 'DUMP P1'!$A$3:$H$10000, _xlpm.filtered, _xlfn._xlws.FILTER(_xlpm.data,'DUMP P1'!$B$3:$B$10000='Fuel Consumption P1'!I6), _xlpm.EOL, _xlfn.CHOOSECOLS(_xlpm.filtered,7), _xlpm.Error, _xlfn.CHOOSECOLS(_xlpm.filtered,8), AVERAGE(_xlpm.Error*_xlpm.EOL))} -> 3.02003 | AB6: Lap 3 | AC6: =$C$5 -> 2.9371875 | AD6: =$D$5 -> 3.0040172 | AE6: =$E$5 -> 3.0314683
B7: 61 Laps | C7: =C5*61 -> 179.16844 | D7: =D5*61 -> 183.24505 | E7: =E5*61 -> 184.91957 | G7: Ford | H7: 6 | I7: Cam Waters, TR28 | J7: 9 | K7: {=_xlfn.LET(_xlpm.data, 'DUMP P1'!$A$3:$H$10000, _xlpm.filtered, _xlfn._xlws.FILTER(_xlpm.data,'DUMP P1'!$B$3:$B$10000='Fuel Consumption P1'!I7), _xlpm.EOL, _xlfn.CHOOSECOLS(_xlpm.filtered,7), _xlpm.Error, _xlfn.CHOOSECOLS(_xlpm.filtered,8), AVERAGE(_xlpm.Error*_xlpm.EOL))} -> 3.03179 | AB7: Lap 4 | AC7: =$C$5 -> 2.9371875 | AD7: =$D$5 -> 3.0040172 | AE7: =$E$5 -> 3.0314683
B8: Out, Formation & In Lap | C8: =1.5*C5 -> 4.4057812 | D8: =1.5*D5 -> 4.5060258 | E8: =1.5*E5 -> 4.5472025 | G8: Ford | H8: 55 | I8: Thomas Randle, TR26 | J8: 9 | K8: {=_xlfn.LET(_xlpm.data, 'DUMP P1'!$A$3:$H$10000, _xlpm.filtered, _xlfn._xlws.FILTER(_xlpm.data,'DUMP P1'!$B$3:$B$10000='Fuel Consumption P1'!I8), _xlpm.EOL, _xlfn.CHOOSECOLS(_xlpm.filtered,7), _xlpm.Error, _xlfn.CHOOSECOLS(_xlpm.filtered,8), AVERAGE(_xlpm.Error*_xlpm.EOL))} -> 2.9762444 | AB8: Lap 5 | AC8: =$C$5 -> 2.9371875 | AD8: =$D$5 -> 3.0040172 | AE8: =$E$5 -> 3.0314683
G9: GM | H9: 4 | I9: Jack Le Brocq, MSR-005 | J9: 4 | K9: {=_xlfn.LET(_xlpm.data, 'DUMP P1'!$A$3:$H$10000, _xlpm.filtered, _xlfn._xlws.FILTER(_xlpm.data,'DUMP P1'!$B$3:$B$10000='Fuel Consumption P1'!I9), _xlpm.EOL, _xlfn.CHOOSECOLS(_xlpm.filtered,7), _xlpm.Error, _xlfn.CHOOSECOLS(_xlpm.filtered,8), AVERAGE(_xlpm.Error*_xlpm.EOL))} -> 2.968875 | AB9: Lap 6 | AC9: =$C$5 -> 2.9371875 | AD9: =$D$5 -> 3.0040172 | AE9: =$E$5 -> 3.0314683
B10: Total | C10: =C7+C8 -> 183.57422 | D10: =D7+D8 -> 187.75108 | E10: =E7+E8 -> 189.46677 | G10: GM | H10: 20 | I10: David Reynolds, T18-003 | J10: 3 | K10: {=_xlfn.LET(_xlpm.data, 'DUMP P1'!$A$3:$H$10000, _xlpm.filtered, _xlfn._xlws.FILTER(_xlpm.data,'DUMP P1'!$B$3:$B$10000='Fuel Consumption P1'!I10), _xlpm.EOL, _xlfn.CHOOSECOLS(_xlpm.filtered,7), _xlpm.Error, _xlfn.CHOOSECOLS(_xlpm.filtered,8), AVERAGE(_xlpm.Error*_xlpm.EOL))} -> 2.9055 | AB10: Lap 7 | AC10: =$C$5 -> 2.9371875 | AD10: =$D$5 -> 3.0040172 | AE10: =$E$5 -> 3.0314683
B11: Fuel to Add (131.5L) | C11: =C10-131.5 -> 52.074219 | D11: =D10-131.5 -> 56.251076 | E11: =E10-131.5 -> 57.966771 | AB11: Lap 8 | AC11: =$C$5 -> 2.9371875 | AD11: =$D$5 -> 3.0040172 | AE11: =$E$5 -> 3.0314683
AB12: Lap 9 | AC12: =$C$5 -> 2.9371875 | AD12: =$D$5 -> 3.0040172 | AE12: =$E$5 -> 3.0314683

Sheet DUMP P1
A1: Fuel Behaviour | G1: Fuel Used EOL [l] | H1: Fuel Error
G2: Avg | H2: Avg
A3: Ruapuna Raceway, Christchurch Super 440 | B3: Jack Le Brocq, MSR-005 | C3: 17/04/2026, Practice 1 | D3: 9:56:03 AM, Run 2 | E3: Lap 1 | F3: 0.00096689815 | G3: 3.07 | H3: 0.975 | I3: =G3*H3 -> 2.99325
A4: Ruapuna Raceway, Christchurch Super 440 | B4: Jack Le Brocq, MSR-005 | C4: 17/04/2026, Practice 1 | D4: 9:56:03 AM, Run 2 | E4: Lap 2 | F4: 0.00096436343 | G4: 3.08 | H4: 0.975 | I4: =G4*H4 -> 3.003
A5: Ruapuna Raceway, Christchurch Super 440 | B5: Jack Le Brocq, MSR-005 | C5: 17/04/2026, Practice 1 | D5: 9:56:03 AM, Run 2 | E5: Lap 3 | F5: 0.00096650463 | G5: 3.01 | H5: 0.975 | I5: =G5*H5 -> 2.93475
A6: Ruapuna Raceway, Christchurch Super 440 | B6: Jack Le Brocq, MSR-005 | C6: 17/04/2026, Practice 1 | D6: 9:56:03 AM, Run 2 | E6: Lap 4 | F6: 0.00096582176 | G6: 3.02 | H6: 0.975 | I6: =G6*H6 -> 2.9445
A7: Ruapuna Raceway, Christchurch Super 440 | B7: David Reynolds, T18-003 | C7: 17/04/2026, Practice 1 | D7: 9:59:25 AM, Run 2 | E7: Lap 1 | F7: 0.00095983796 | G7: 2.97 | H7: 0.975 | I7: =G7*H7 -> 2.89575
A8: Ruapuna Raceway, Christchurch Super 440 | B8: David Reynolds, T18-003 | C8: 17/04/2026, Practice 1 | D8: 9:59:25 AM, Run 2 | E8: Lap 2 | F8: 0.00095952546 | G8: 2.95 | H8: 0.975 | I8: =G8*H8 -> 2.87625
A9: Ruapuna Raceway, Christchurch Super 440 | B9: David Reynolds, T18-003 | C9: 17/04/2026, Practice 1 | D9: 9:59:25 AM, Run 2 | E9: Lap 3 | F9: 0.00095846065 | G9: 3.02 | H9: 0.975 | I9: =G9*H9 -> 2.9445
A10: Ruapuna Raceway, Christchurch Super 440 | B10: Thomas Randle, TR26 | C10: 17/04/2026, Practice 1 | D10: 10:03:25 AM, Run 2 | E10: Lap 1 | F10: 0.00096070602 | G10: 2.94 | H10: 1.007 | I10: =G10*H10 -> 2.96058
A11: Ruapuna Raceway, Christchurch Super 440 | B11: Thomas Randle, TR26 | C11: 17/04/2026, Practice 1 | D11: 10:03:25 AM, Run 2 | E11: Lap 2 | F11: 0.00095596065 | G11: 3 | H11: 1.007 | I11: =G11*H11 -> 3.021
A12: Ruapuna Raceway, Christchurch Super 440 | B12: Thomas Randle, TR26 | C12: 17/04/2026, Practice 1 | D12: 10:03:25 AM, Run 2 | E12: Lap 3 | F12: 0.00095956019 | G12: 2.99 | H12: 1.007 | I12: =G12*H12 -> 3.01093
A13: Ruapuna Raceway, Christchurch Super 440 | B13: Thomas Randle, TR26 | C13: 17/04/2026, Practice 1 | D13: 10:03:25 AM, Run 2 | E13: Lap 4 | F13: 0.00096086806 | G13: 2.95 | H13: 1.007 | I13: =G13*H13 -> 2.97065
A14: Ruapuna Raceway, Christchurch Super 440 | B14: Thomas Randle, TR26 | C14: 17/04/2026, Practice 1 | D14: 10:03:25 AM, Run 2 | E14: Lap 5 | F14: 0.00096310185 | G14: 2.98 | H14: 1.007 | I14: =G14*H14 -> 3.00086
... A38: Ruapuna Raceway, Christchurch Super440 | B38: Andre Heimgartner, BJR019 | C38: 17/04/2026, Practice 1 | D38: 10:01:19 AM, Run 02 | E38: Lap 6 | F38: 0.00098697917 | G38: 3.34 | H38: 0.848 | I38: =G38*H38 -> 2.83232

Sheet FC R10
B2: Fuel Consumption - 04 RUA
B4: Lap Count | C4: 61
B5: Out, Formation, In | C5: 1.5
B6: Usable Tank [l] | C6: 130.5
B7: Churn Size [l] | C7: 25 | AS7: GM | AT7: Ford | AU7: Toyota
B8: Churn Limit In Question | C8: 2
B9: Fuel Density (kg/L) | C9: =FuelDensity/1000 -> 0.789646 | AR9: Lap 1 | AS9: =#REF! -> #REF! | AT9: =#REF! -> #REF! | AU9: =#REF! -> #REF!
AR10: Lap 2 | AS10: =#REF! -> #REF! | AT10: =#REF! -> #REF! | AU10: =#REF! -> #REF!
B11: Fuel Density Calculator
B12: Fuel Temp
B13: See 'Fuel Properties' Sheet
G15: Average | M15: Max | AS15: Lap 3 | AT15: =#REF! -> #REF! | AU15: =#REF! -> #REF! | AV15: =#REF! -> #REF!
B16: DASH | C16: Av Fuel Used [kg] | D16: Av Fuel Used [l] | E16: Max Fuel Used [l] | G16: Race Laps | H16: Out, F, In (1.5 Laps) | I16: Total Required | J16: Fuel Requied | K16: Churn Required | M16: Race Laps | N16: Out, F, In (1.5 Laps) | O16: Total Required | P16: Fuel Requied | Q16: Churn Required | AS16: Lap 4 | AT16: =#REF! -> #REF! | AU16: =#REF! -> #REF! | AV16: =#REF! -> #REF!
B17: GM | C17: {=_xlfn.LET(_xlpm.data, $W$43:$AB$62, _xlpm.filtered, _xlfn._xlws.FILTER(_xlpm.data, $W$43:$W$62='FC R10'!$B17), _xlpm.EOL, _xlfn.CHOOSECOLS(_xlpm.filtered,3), AVERAGE(_xlpm.EOL))} -> 2.2230606 | D17: {=_xlfn.LET(_xlpm.data, $W$43:$AB$62, _xlpm.filtered, _xlfn._xlws.FILTER(_xlpm.data, $W$43:$W$62='FC R10'!$B17), _xlpm.EOL, _xlfn.CHOOSECOLS(_xlpm.filtered,5), AVERAGE(_xlpm.EOL))} -> 2.8152623 | E17: {=_xlfn.LET(_xlpm.data, $W$43:$AB$62, _xlpm.filtered, _xlfn._xlws.FILTER(_xlpm.data, $W$43:$W$62='FC R10'!$B17), _xlpm.EOL, _xlfn.CHOOSECOLS(_xlpm.filtered,5), MAX(_xlpm.EOL))} -> 2.8590622 | G17: =D17*$C$4 -> 171.731 | H17: =D17*$C$5 -> 4.2228934 | I17: =SUM(G17:H17) -> 175.95389 | J17: =I17-$C$6 -> 45.453893 | K17: =J17/$C$7 -> 1.8181557 | M17: =E17*$C$4 -> 174.4028 | N17: =E17*1.5 -> 4.2885934 | O17: =SUM(M17:N17) -> 178.69139 | P17: =O17-$C$6 -> 48.19139 | Q17: =P17/$C$7 -> 1.9276556 | AS17: Lap 5 | AT17: =#REF! -> #REF! | AU17: =#REF! -> #REF! | AV17: =#REF! -> #REF!
B18: Ford | C18: {=_xlfn.LET(_xlpm.data, $W$43:$AB$62, _xlpm.filtered, _xlfn._xlws.FILTER(_xlpm.data, $W$43:$W$62='FC R10'!$B18), _xlpm.EOL, _xlfn.CHOOSECOLS(_xlpm.filtered,3), AVERAGE(_xlpm.EOL))} -> 2.18231 | D18: {=_xlfn.LET(_xlpm.data, $W$43:$AB$62, _xlpm.filtered, _xlfn._xlws.FILTER(_xlpm.data, $W$43:$W$62='FC R10'!$B18), _xlpm.EOL, _xlfn.CHOOSECOLS(_xlpm.filtered,5), AVERAGE(_xlpm.EOL))} -> 2.7636561 | E18: {=_xlfn.LET(_xlpm.data, $W$43:$AB$62, _xlpm.filtered, _xlfn._xlws.FILTER(_xlpm.data, $W$43:$W$62='FC R10'!$B18), _xlpm.EOL, _xlfn.CHOOSECOLS(_xlpm.filtered,5), MAX(_xlpm.EOL))} -> 2.8661391 | G18: =D18*$C$4 -> 168.58302 | H18: =D18*$C$5 -> 4.1454842 | I18: =SUM(G18:H18) -> 172.72851 | J18: =I18-$C$6 -> 42.228507 | K18: =J18/$C$7 -> 1.6891403 | M18: =E18*$C$4 -> 174.83449 | N18: =E18*1.5 -> 4.2992087 | O18: =SUM(M18:N18) -> 179.1337 | P18: =O18-$C$6 -> 48.633695 | Q18: =P18/$C$7 -> 1.9453478 | AS18: Lap 6 | AT18: =#REF! -> #REF! | AU18: =#REF! -> #REF! | AV18: =#REF! -> #REF!
B19: Toyota | C19: {=_xlfn.LET(_xlpm.data, $W$43:$AB$62, _xlpm.filtered, _xlfn._xlws.FILTER(_xlpm.data, $W$43:$W$62='FC R10'!$B19), _xlpm.EOL, _xlfn.CHOOSECOLS(_xlpm.filtered,3), AVERAGE(_xlpm.EOL))} -> 2.2103235 | D19: {=_xlfn.LET(_xlpm.data, $W$43:$AB$62, _xlpm.filtered, _xlfn._xlws.FILTER(_xlpm.data, $W$43:$W$62='FC R10'!$B19), _xlpm.EOL, _xlfn.CHOOSECOLS(_xlpm.filtered,5), AVERAGE(_xlpm.EOL))} -> 2.7991322 | E19: {=_xlfn.LET(_xlpm.data, $W$43:$AB$62, _xlpm.filtered, _xlfn._xlws.FILTER(_xlpm.data, $W$43:$W$62='FC R10'!$B19), _xlpm.EOL, _xlfn.CHOOSECOLS(_xlpm.filtered,5), MAX(_xlpm.EOL))} -> 2.9013001 | G19: =D19*$C$4 -> 170.74706 | H19: =D19*$C$5 -> 4.1986983 | I19: =SUM(G19:H19) -> 174.94576 | J19: =I19-$C$6 -> 44.445761 | K19: =J19/$C$7 -> 1.7778305 | M19: =E19*$C$4 -> 176.9793 | N19: =E19*1.5 -> 4.3519501 | O19: =SUM(M19:N19) -> 181.33125 | P19: =O19-$C$6 -> 50.831255 | Q19: =P19/$C$7 -> 2.0332502 | AS19: Lap 7 | AT19: =#REF! -> #REF! | AU19: =#REF! -> #REF! | AV19: =#REF! -> #REF!
B20: * Dash Calculates Fuel Used in Kg, Fuel Error is included in the number | AS20: Lap 8 | AT20: =#REF! -> #REF! | AU20: =#REF! -> #REF! | AV20: =#REF! -> #REF!
AS21: Lap 9 | AT21: =#REF! -> #REF! | AU21: =#REF! -> #REF! | AV21: =#REF! -> #REF!
G28: Average | M28: Max
B29: ECU | D29: Av Fuel Used [l] | E29: Max Fuel Used [l] | G29: Race Laps | H29: Out, F, In (1.5 Laps) | I29: Total Required | J29: Fuel Requied | K29: Churn Required | M29: Race Laps | N29: Out, F, In (1.5 Laps) | O29: Total Required | P29: Fuel Requied | Q29: Churn Required
B30: GM | D30: {=_xlfn.LET(_xlpm.data, $W$43:$AB$62, _xlpm.filtered, _xlfn._xlws.FILTER(_xlpm.data, $W$43:$W$62='FC R10'!$B30), _xlpm.EOL, _xlfn.CHOOSECOLS(_xlpm.filtered,6), AVERAGE(_xlpm.EOL))} -> 2.7768139 | E30: {=_xlfn.LET(_xlpm.data, $W$43:$AB$62, _xlpm.filtered, _xlfn._xlws.FILTER(_xlpm.data, $W$43:$W$62='FC R10'!$B30), _xlpm.EOL, _xlfn.CHOOSECOLS(_xlpm.filtered,6), MAX(_xlpm.EOL))} -> 2.8252676 | G30: =D30*$C$4 -> 169.38564 | H30: =D30*$C$5 -> 4.1652208 | I30: =SUM(G30:H30) -> 173.55087 | J30: =I30-$C$6 -> 43.050866 | K30: =J30/$C$7 -> 1.7220346 | M30: =E30*$C$4 -> 172.34133 | N30: =E30*1.5 -> 4.2379015 | O30: =SUM(M30:N30) -> 176.57923 | P30: =O30-$C$6 -> 46.079228 | Q30: =P30/$C$7 -> 1.8431691
B31: Ford | D31: {=_xlfn.LET(_xlpm.data, $W$43:$AB$62, _xlpm.filtered, _xlfn._xlws.FILTER(_xlpm.data, $W$43:$W$62='FC R10'!$B31), _xlpm.EOL, _xlfn.CHOOSECOLS(_xlpm.filtered,6), AVERAGE(_xlpm.EOL))} -> 2.826271 | E31: {=_xlfn.LET(_xlpm.data, $W$43:$AB$62, _xlpm.filtered, _xlfn._xlws.FILTER(_xlpm.data, $W$43:$W$62='FC R10'!$B31), _xlpm.EOL, _xlfn.CHOOSECOLS(_xlpm.filtered,6), MAX(_xlpm.EOL))} -> 2.9269206 | G31: =D31*$C$4 -> 172.40253 | H31: =D31*$C$5 -> 4.2394064 | I31: =SUM(G31:H31) -> 176.64193 | J31: =I31-$C$6 -> 46.141935 | K31: =J31/$C$7 -> 1.8456774 | M31: =E31*$C$4 -> 178.54216 | N31: =E31*1.5 -> 4.3903809 | O31: =SUM(M31:N31) -> 182.93254 | P31: =O31-$C$6 -> 52.432537 | Q31: =P31/$C$7 -> 2.0973015
B32: Toyota | D32: {=_xlfn.LET(_xlpm.data, $W$43:$AB$62, _xlpm.filtered, _xlfn._xlws.FILTER(_xlpm.data, $W$43:$W$62='FC R10'!$B32), _xlpm.EOL, _xlfn.CHOOSECOLS(_xlpm.filtered,6), AVERAGE(_xlpm.EOL))} -> 2.9084411 | E32: {=_xlfn.LET(_xlpm.data, $W$43:$AB$62, _xlpm.filtered, _xlfn._xlws.FILTER(_xlpm.data, $W$43:$W$62='FC R10'!$B32), _xlpm.EOL, _xlfn.CHOOSECOLS(_xlpm.filtered,6), MAX(_xlpm.EOL))} -> 3.0059467 | G32: =D32*$C$4 -> 177.41491 | H32: =D32*$C$5 -> 4.3626616 | I32: =SUM(G32:H32) -> 181.77757 | J32: =I32-$C$6 -> 51.277567 | K32: =J32/$C$7 -> 2.0511027 | M32: =E32*$C$4 -> 183.36275 | N32: =E32*1.5 -> 4.50892 | O32: =SUM(M32:N32) -> 187.87167 | P32: =O32-$C$6 -> 57.371667 | Q32: =P32/$C$7 -> 2.2948667
B33: * ECU Sends Fuel Used in l, then combined with Fuel Error.
B34: * PROBLEM: Fuel Error is used to calibrate the Fuel Use from the Dash, no guarantee it is the same with the ECU
W42: Make | X42: Driver | Y42: Fuel Used Dash Average [kg] | AA42: Fuel Used Dash Average [l] | AB42: Fuel Used ECU Average [l] | AD42: Error
W43: Toyota | X43: {=_xlfn._xlws.FILTER(_xlfn.UNIQUE('DUMP R10'!B:B),_xlfn.UNIQUE('DUMP R10'!B:B)<>0)} -> Andre Heimgartner, BJR019 | Y43: {=_xlfn.LET(_xlpm.data, 'DUMP R10'!$A$3:$J$10000, _xlpm.filtered, _xlfn._xlws.FILTER(_xlpm.data,'DUMP R10'!$B$3:$B$10000=$X43), _xlpm.EOL_Dash, _xlfn.CHOOSECOLS(_xlpm.filtered,7), AVERAGE(_xlpm.EOL_Dash))} -> 2.2226471 | AA43: =Y43/$C$9 -> 2.8147386 | AB43: {=_xlfn.LET(_xlpm.data, 'DUMP R10'!$A$3:$J$10000, _xlpm.filtered, _xlfn._xlws.FILTER(_xlpm.data,'DUMP R10'!$B$3:$B$10000=$X43), _xlpm.EOL_w_Error, _xlfn.CHOOSECOLS(_xlpm.filtered,10), AVERAGE(_xlpm.EOL_w_Error))} -> 2.92984 | AD43: =1-AB43/AA43 -> -0.040892402
W44: Ford | X44: Thomas Randle, TR26 | Y44: {=_xlfn.LET(_xlpm.data, 'DUMP R10'!$A$3:$J$10000, _xlpm.filtered, _xlfn._xlws.FILTER(_xlpm.data,'DUMP R10'!$B$3:$B$10000=$X44), _xlpm.EOL_Dash, _xlfn.CHOOSECOLS(_xlpm.filtered,7), AVERAGE(_xlpm.EOL_Dash))} -> 2.1544118 | AA44: =Y44/$C$9 -> 2.7283261 | AB44: {=_xlfn.LET(_xlpm.data, 'DUMP R10'!$A$3:$J$10000, _xlpm.filtered, _xlfn._xlws.FILTER(_xlpm.data,'DUMP R10'!$B$3:$B$10000=X44), _xlpm.EOL_w_Error, _xlfn.CHOOSECOLS(_xlpm.filtered,10), AVERAGE(_xlpm.EOL_w_Error))} -> 2.7950174 | AD44: =1-AB44/AA44 -> -0.024444031
W45: Ford | X45: Rylan Gray, DJRS08-MR | Y45: {=_xlfn.LET(_xlpm.data, 'DUMP R10'!$A$3:$J$10000, _xlpm.filtered, _xlfn._xlws.FILTER(_xlpm.data,'DUMP R10'!$B$3:$B$10000=$X45), _xlpm.EOL_Dash, _xlfn.CHOOSECOLS(_xlpm.filtered,7), AVERAGE(_xlpm.EOL_Dash))} -> 2.1291176 | AA45: =Y45/$C$9 -> 2.6962938 | AB45: {=_xlfn.LET(_xlpm.data, 'DUMP R10'!$A$3:$J$10000, _xlpm.filtered, _xlfn._xlws.FILTER(_xlpm.data,'DUMP R10'!$B$3:$B$10000=X45), _xlpm.EOL_w_Error, _xlfn.CHOOSECOLS(_xlpm.filtered,10), AVERAGE(_xlpm.EOL_w_Error))} -> 2.7597059 | AD45: =1-AB45/AA45 -> -0.023518223
W46: Ford | X46: Cam Waters, TR28 | Y46: {=_xlfn.LET(_xlpm.data, 'DUMP R10'!$A$3:$J$10000, _xlpm.filtered, _xlfn._xlws.FILTER(_xlpm.data,'DUMP R10'!$B$3:$B$10000=$X46), _xlpm.EOL_Dash, _xlfn.CHOOSECOLS(_xlpm.filtered,7), AVERAGE(_xlpm.EOL_Dash))} -> 2.2167647 | AA46: =Y46/$C$9 -> 2.8072892 | AB46: {=_xlfn.LET(_xlpm.data, 'DUMP R10'!$A$3:$J$10000, _xlpm.filtered, _xlfn._xlws.FILTER(_xlpm.data,'DUMP R10'!$B$3:$B$10000=X46), _xlpm.EOL_w_Error, _xlfn.CHOOSECOLS(_xlpm.filtered,10), AVERAGE(_xlpm.EOL_w_Error))} -> 2.8760162 | AD46: =1-AB46/AA46 -> -0.024481608
W47: GM | X47: Jayden Ojeda, 888A-064 | Y47: {=_xlfn.LET(_xlpm.data, 'DUMP R10'!$A$3:$J$10000, _xlpm.filtered, _xlfn._xlws.FILTER(_xlpm.data,'DUMP R10'!$B$3:$B$10000=$X47), _xlpm.EOL_Dash, _xlfn.CHOOSECOLS(_xlpm.filtered,7), AVERAGE(_xlpm.EOL_Dash))} -> 2.1714706 | AA47: =Y47/$C$9 -> 2.7499292 | AB47: {=_xlfn.LET(_xlpm.data, 'DUMP R10'!$A$3:$J$10000, _xlpm.filtered, _xlfn._xlws.FILTER(_xlpm.data,'DUMP R10'!$B$3:$B$10000=X47), _xlpm.EOL_w_Error, _xlfn.CHOOSECOLS(_xlpm.filtered,10), AVERAGE(_xlpm.EOL_w_Error))} -> 2.7059118 | AD47: =1-AB47/AA47 -> 0.01600675
W48: Ford | X48: Broc Feeney, 888A-072 | Y48: {=_xlfn.LET(_xlpm.data, 'DUMP R10'!$A$3:$J$10000, _xlpm.filtered, _xlfn._xlws.FILTER(_xlpm.data,'DUMP R10'!$B$3:$B$10000=$X48), _xlpm.EOL_Dash, _xlfn.CHOOSECOLS(_xlpm.filtered,7), AVERAGE(_xlpm.EOL_Dash))} -> 2.155 | AA48: =Y48/$C$9 -> 2.729071 | AB48: {=_xlfn.LET(_xlpm.data, 'DUMP R10'!$A$3:$J$10000, _xlpm.filtered, _xlfn._xlws.FILTER(_xlpm.data,'DUMP R10'!$B$3:$B$10000=X48), _xlpm.EOL_w_Error, _xlfn.CHOOSECOLS(_xlpm.filtered,10), AVERAGE(_xlpm.EOL_w_Error))} -> 2.7937588 | AD48: =1-AB48/AA48 -> -0.023703239
W49: GM | X49: Zach Bates, MSR-006 | Y49: {=_xlfn.LET(_xlpm.data, 'DUMP R10'!$A$3:$J$10000, _xlpm.filtered, _xlfn._xlws.FILTER(_xlpm.data,'DUMP R10'!$B$3:$B$10000=$X49), _xlpm.EOL_Dash, _xlfn.CHOOSECOLS(_xlpm.filtered,7), AVERAGE(_xlpm.EOL_Dash))} -> 2.2476471 | AA49: =Y49/$C$9 -> 2.8463983 | AB49: {=_xlfn.LET(_xlpm.data, 'DUMP R10'!$A$3:$J$10000, _xlpm.filtered, _xlfn._xlws.FILTER(_xlpm.data,'DUMP R10'!$B$3:$B$10000=X49), _xlpm.EOL_w_Error, _xlfn.CHOOSECOLS(_xlpm.filtered,10), AVERAGE(_xlpm.EOL_w_Error))} -> 2.8013029 | AD49: =1-AB49/AA49 -> 0.015842966
W50: Ford | X50: Will Brown, 888A-073 | Y50: {=_xlfn.LET(_xlpm.data, 'DUMP R10'!$A$3:$J$10000, _xlpm.filtered, _xlfn._xlws.FILTER(_xlpm.data,'DUMP R10'!$B$3:$B$10000=$X50), _xlpm.EOL_Dash, _xlfn.CHOOSECOLS(_xlpm.filtered,7), AVERAGE(_xlpm.EOL_Dash))} -> 2.1994118 | AA50: =Y50/$C$9 -> 2.7853136 | AB50: {=_xlfn.LET(_xlpm.data, 'DUMP R10'!$A$3:$J$10000, _xlpm.filtered, _xlfn._xlws.FILTER(_xlpm.data,'DUMP R10'!$B$3:$B$10000=X50), _xlpm.EOL_w_Error, _xlfn.CHOOSECOLS(_xlpm.filtered,10), AVERAGE(_xlpm.EOL_w_Error))} -> 2.8432941 | AD50: =1-AB50/AA50 -> -0.020816503
W51: GM | X51: Jack Le Brocq, MSR-005 | Y51: {=_xlfn.LET(_xlpm.data, 'DUMP R10'!$A$3:$J$10000, _xlpm.filtered, _xlfn._xlws.FILTER(_xlpm.data,'DUMP R10'!$B$3:$B$10000=$X51), _xlpm.EOL_Dash, _xlfn.CHOOSECOLS(_xlpm.filtered,7), AVERAGE(_xlpm.EOL_Dash))} -> 2.2082353 | AA51: =Y51/$C$9 -> 2.7964877 | AB51: {=_xlfn.LET(_xlpm.data, 'DUMP R10'!$A$3:$J$10000, _xlpm.filtered, _xlfn._xlws.FILTER(_xlpm.data,'DUMP R10'!$B$3:$B$10000=X51), _xlpm.EOL_w_Error, _xlfn.CHOOSECOLS(_xlpm.filtered,10), AVERAGE(_xlpm.EOL_w_Error))} -> 2.7661324 | AD51: =1-AB51/AA51 -> 0.010854797
W52: Ford | X52: James Golding, BRT-002 | Y52: {=_xlfn.LET(_xlpm.data, 'DUMP R10'!$A$3:$J$10000, _xlpm.filtered, _xlfn._xlws.FILTER(_xlpm.data,'DUMP R10'!$B$3:$B$10000=$X52), _xlpm.EOL_Dash, _xlfn.CHOOSECOLS(_xlpm.filtered,7), AVERAGE(_xlpm.EOL_Dash))} -> 2.2038235 | AA52: =Y52/$C$9 -> 2.7909006 | AB52: {=_xlfn.LET(_xlpm.data, 'DUMP R10'!$A$3:$J$10000, _xlpm.filtered, _xlfn._xlws.FILTER(_xlpm.data,'DUMP R10'!$B$3:$B$10000=X52), _xlpm.EOL_w_Error, _xlfn.CHOOSECOLS(_xlpm.filtered,10), AVERAGE(_xlpm.EOL_w_Error))} -> 2.8560235 | AD52: =1-AB52/AA52 -> -0.023334004
W53: Ford | X53: Jackson Walls, 888A-074 | Y53: {=_xlfn.LET(_xlpm.data, 'DUMP R10'!$A$3:$J$10000, _xlpm.filtered, _xlfn._xlws.FILTER(_xlpm.data,'DUMP R10'!$B$3:$B$10000=$X53), _xlpm.EOL_Dash, _xlfn.CHOOSECOLS(_xlpm.filtered,7), AVERAGE(_xlpm.EOL_Dash))} -> 2.1164706 | AA53: =Y53/$C$9 -> 2.6802777 | AB53: {=_xlfn.LET(_xlpm.data, 'DUMP R10'!$A$3:$J$10000, _xlpm.filtered, _xlfn._xlws.FILTER(_xlpm.data,'DUMP R10'!$B$3:$B$10000=X53), _xlpm.EOL_w_Error, _xlfn.CHOOSECOLS(_xlpm.filtered,10), AVERAGE(_xlpm.EOL_w_Error))} -> 2.73632 | AD53: =1-AB53/AA53 -> -0.020909128
W54: Toyota | X54: Chaz Mostert, WR-032 | Y54: {=_xlfn.LET(_xlpm.data, 'DUMP R10'!$A$3:$J$10000, _xlpm.filtered, _xlfn._xlws.FILTER(_xlpm.data,'DUMP R10'!$B$3:$B$10000=$X54), _xlpm.EOL_Dash, _xlfn.CHOOSECOLS(_xlpm.filtered,7), AVERAGE(_xlpm.EOL_Dash))} -> 2.1591176 | AA54: =Y54/$C$9 -> 2.7342855 | AB54: {=_xlfn.LET(_xlpm.data, 'DUMP R10'!$A$3:$J$10000, _xlpm.filtered, _xlfn._xlws.FILTER(_xlpm.data,'DUMP R10'!$B$3:$B$10000=X54), _xlpm.EOL_w_Error, _xlfn.CHOOSECOLS(_xlpm.filtered,10), AVERAGE(_xlpm.EOL_w_Error))} -> 2.8395671 | AD54: =1-AB54/AA54 -> -0.038504212
W55: Ford | X55: Aaron Cameron, BRT-001 | Y55: {=_xlfn.LET(_xlpm.data, 'DUMP R10'!$A$3:$J$10000, _xlpm.filtered, _xlfn._xlws.FILTER(_xlpm.data,'DUMP R10'!$B$3:$B$10000=$X55), _xlpm.EOL_Dash, _xlfn.CHOOSECOLS(_xlpm.filtered,7), AVERAGE(_xlpm.EOL_Dash))} -> 2.2139394 | AA55: =Y55/$C$9 -> 2.8037113 | AB55: {=_xlfn.LET(_xlpm.data, 'DUMP R10'!$A$3:$J$10000, _xlpm.filtered, _xlfn._xlws.FILTER(_xlpm.data,'DUMP R10'!$B$3:$B$10000=X55), _xlpm.EOL_w_Error, _xlfn.CHOOSECOLS(_xlpm.filtered,10), AVERAGE(_xlpm.EOL_w_Error))} -> 2.8630182 | AD55: =1-AB55/AA55 -> -0.021153001
... W62: Ford | X62: Kai Allen, GR-03 | Y62: {=_xlfn.LET(_xlpm.data, 'DUMP R10'!$A$3:$J$10000, _xlpm.filtered, _xlfn._xlws.FILTER(_xlpm.data,'DUMP R10'!$B$3:$B$10000=$X62), _xlpm.EOL_Dash, _xlfn.CHOOSECOLS(_xlpm.filtered,7), AVERAGE(_xlpm.EOL_Dash))} -> 2.2102941 | AA62: =Y62/$C$9 -> 2.7990949 | AB62: {=_xlfn.LET(_xlpm.data, 'DUMP R10'!$A$3:$J$10000, _xlpm.filtered, _xlfn._xlws.FILTER(_xlpm.data,'DUMP R10'!$B$3:$B$10000=X62), _xlpm.EOL_w_Error, _xlfn.CHOOSECOLS(_xlpm.filtered,10), AVERAGE(_xlpm.EOL_w_Error))} -> 2.8600824 | AD62: =1-AB62/AA62 -> -0.021788264

Sheet DUMP R10
A1: Fuel Behaviour | G1: Fuel Used Dash EOL [kg] | H1: Fuel Used ECU EOL [l] | I1: Fuel Error | J1: Fuel Used ECU [l]
G2: Avg | H2: Avg | I2: Avg
A3: Ruapuna Raceway, Christchurch Super440 | B3: Andre Heimgartner, BJR019 | C3: 17/04/2026, Race 10 | D3: 5:35:01 PM, P13 | E3: Lap 3 | F3: 0.00099381944 | G3: 2.14 | H3: 3.32 | I3: 0.848 | J3: =H3*I3 -> 2.81536
A4: Ruapuna Raceway, Christchurch Super440 | B4: Andre Heimgartner, BJR019 | C4: 17/04/2026, Race 10 | D4: 5:35:01 PM, P13 | E4: Lap 4 | F4: 0.00098560185 | G4: 2.09 | H4: 3.27 | I4: 0.848 | J4: =H4*I4 -> 2.77296
A5: Ruapuna Raceway, Christchurch Super440 | B5: Andre Heimgartner, BJR019 | C5: 17/04/2026, Race 10 | D5: 5:35:01 PM, P13 | E5: Lap 5 | F5: 0.00098211806 | G5: 2.11 | H5: 3.3 | I5: 0.848 | J5: =H5*I5 -> 2.7984
A6: Ruapuna Raceway, Christchurch Super440 | B6: Andre Heimgartner, BJR019 | C6: 17/04/2026, Race 10 | D6: 5:35:01 PM, P13 | E6: Lap 6 | F6: 0.00098224537 | G6: 2.12 | H6: 3.3 | I6: 0.848 | J6: =H6*I6 -> 2.7984
A7: Ruapuna Raceway, Christchurch Super440 | B7: Andre Heimgartner, BJR019 | C7: 17/04/2026, Race 10 | D7: 5:35:01 PM, P13 | E7: Lap 7 | F7: 0.00097726852 | G7: 2.22 | H7: 3.45 | I7: 0.848 | J7: =H7*I7 -> 2.9256
A8: Ruapuna Raceway, Christchurch Super440 | B8: Andre Heimgartner, BJR019 | C8: 17/04/2026, Race 10 | D8: 5:35:01 PM, P13 | E8: Lap 8 | F8: 0.00097600694 | G8: 2.23 | H8: 3.46 | I8: 0.848 | J8: =H8*I8 -> 2.93408
A9: Ruapuna Raceway, Christchurch Super440 | B9: Andre Heimgartner, BJR019 | C9: 17/04/2026, Race 10 | D9: 5:35:01 PM, P13 | E9: Lap 9 | F9: 0.0009750463 | G9: 2.22 | H9: 3.43 | I9: 0.848 | J9: =H9*I9 -> 2.90864
A10: Ruapuna Raceway, Christchurch Super440 | B10: Andre Heimgartner, BJR019 | C10: 17/04/2026, Race 10 | D10: 5:35:01 PM, P13 | E10: Lap 10 | F10: 0.00097607639 | G10: 2.22 | H10: 3.44 | I10: 0.848 | J10: =H10*I10 -> 2.91712
A11: Ruapuna Raceway, Christchurch Super440 | B11: Andre Heimgartner, BJR019 | C11: 17/04/2026, Race 10 | D11: 5:35:01 PM, P13 | E11: Lap 11 | F11: 0.0009762037 | G11: 2.21 | H11: 3.43 | I11: 0.848 | J11: =H11*I11 -> 2.90864
A12: Ruapuna Raceway, Christchurch Super440 | B12: Andre Heimgartner, BJR019 | C12: 17/04/2026, Race 10 | D12: 5:35:01 PM, P13 | E12: Lap 12 | F12: 0.00097936343 | G12: 2.21 | H12: 3.44 | I12: 0.848 | J12: =H12*I12 -> 2.91712
A13: Ruapuna Raceway, Christchurch Super440 | B13: Andre Heimgartner, BJR019 | C13: 17/04/2026, Race 10 | D13: 5:35:01 PM, P13 | E13: Lap 13 | F13: 0.00097829861 | G13: 2.23 | H13: 3.46 | I13: 0.848 | J13: =H13*I13 -> 2.93408
A14: Ruapuna Raceway, Christchurch Super440 | B14: Andre Heimgartner, BJR019 | C14: 17/04/2026, Race 10 | D14: 5:35:01 PM, P13 | E14: Lap 14 | F14: 0.00097986111 | G14: 2.21 | H14: 3.43 | I14: 0.848 | J14: =H14*I14 -> 2.90864
... A240: Ruapuna Raceway, Christchurch Super 440 | B240: Zach Bates, MSR-006 | C240: 17/04/2026, Race 10 | D240: 5:36:27 PM, Run 1 | E240: Lap 37 | F240: 0.00097556713 | G240: 2.25 | H240: 2.9 | I240: 0.97 | J240: =H240*I240 -> 2.813
A241: Ruapuna Raceway, Christchurch Super 440 | B241: Will Brown, 888A-073 | C241: 17/04/2026, Race 10 | D241: 0.73368056 | E241: Lap 3 | F241: 0.00097790509 | G241: 2.19 | H241: 2.82 | I241: 1.007 | J241: =H241*I241 -> 2.83974
A242: Ruapuna Raceway, Christchurch Super 440 | B242: Will Brown, 888A-073 | C242: 17/04/2026, Race 10 | D242: 0.73368056 | E242: Lap 4 | F242: 0.00096806713 | G242: 2.28 | H242: 2.93 | I242: 1.007 | J242: =H242*I242 -> 2.95051
A243: Ruapuna Raceway, Christchurch Super 440 | B243: Will Brown, 888A-073 | C243: 17/04/2026, Race 10 | D243: 0.73368056 | E243: Lap 5 | F243: 0.00096929398 | G243: 2.27 | H243: 2.91 | I243: 1.007 | J243: =H243*I243 -> 2.93037
A244: Ruapuna Raceway, Christchurch Super 440 | B244: Will Brown, 888A-073 | C244: 17/04/2026, Race 10 | D244: 0.73368056 | E244: Lap 6 | F244: 0.00097015046 | G244: 2.27 | H244: 2.91 | I244: 1.007 | J244: =H244*I244 -> 2.93037
A245: Ruapuna Raceway, Christchurch Super 440 | B245: Will Brown, 888A-073 | C245: 17/04/2026, Race 10 | D245: 0.73368056 | E245: Lap 7 | F245: 0.00097125 | G245: 2.28 | H245: 2.92 | I245: 1.007 | J245: =H245*I245 -> 2.94044
A246: Ruapuna Raceway, Christchurch Super 440 | B246: Will Brown, 888A-073 | C246: 17/04/2026, Race 10 | D246: 0.73368056 | E246: Lap 8 | F246: 0.00097564815 | G246: 2.28 | H246: 2.91 | I246: 1.007 | J246: =H246*I246 -> 2.93037
A247: Ruapuna Raceway, Christchurch Super 440 | B247: Will Brown, 888A-073 | C247: 17/04/2026, Race 10 | D247: 0.73368056 | E247: Lap 9 | F247: 0.00097287037 | G247: 2.27 | H247: 2.9 | I247: 1.007 | J247: =H247*I247 -> 2.9203
A248: Ruapuna Raceway, Christchurch Super 440 | B248: Will Brown, 888A-073 | C248: 17/04/2026, Race 10 | D248: 0.73368056 | E248: Lap 10 | F248: 0.00097091435 | G248: 2.27 | H248: 2.91 | I248: 1.007 | J248: =H248*I248 -> 2.93037
A249: Ruapuna Raceway, Christchurch Super 440 | B249: Will Brown, 888A-073 | C249: 17/04/2026, Race 10 | D249: 0.73368056 | E249: Lap 11 | F249: 0.00097592593 | G249: 2.23 | H249: 2.87 | I249: 1.007 | J249: =H249*I249 -> 2.89009
A250: Ruapuna Raceway, Christchurch Super 440 | B250: Will Brown, 888A-073 | C250: 17/04/2026, Race 10 | D250: 0.73368056 | E250: Lap 12 | F250: 0.00097634259 | G250: 2.26 | H250: 2.89 | I250: 1.007 | J250: =H250*I250 -> 2.91023
A251: Ruapuna Raceway, Christchurch Super 440 | B251: Will Brown, 888A-073 | C251: 17/04/2026, Race 10 | D251: 0.73368056 | E251: Lap 13 | F251: 0.00097865741 | G251: 2.24 | H251: 2.86 | I251: 1.007 | J251: =H251*I251 -> 2.88002
A252: Ruapuna Raceway, Christchurch Super 440 | B252: Will Brown, 888A-073 | C252: 17/04/2026, Race 10 | D252: 0.73368056 | E252: Lap 14 | F252: 0.00097820602 | G252: 2.23 | H252: 2.86 | I252: 1.007 | J252: =H252*I252 -> 2.88002
... A274: Ruapuna Raceway, Christchurch Super 440 | B274: Will Brown, 888A-073 | C274: 17/04/2026, Race 10 | D274: 0.73368056 | E274: Lap 37 | F274: 0.00099978009 | G274: 2.1 | H274: 2.71 | I274: 1.007 | J274: =H274*I274 -> 2.72897
A275: Ruapuna Raceway, Christchurch Super 440 | B275: Jack Le Brocq, MSR-005 | C275: 17/04/2026, Race 10 | D275: 5:36:37 PM, Run 1 | E275: Lap 3 | F275: 0.00099128472 | G275: 2.15 | H275: 2.76 | I275: 0.975 | J275: =H275*I275 -> 2.691
A276: Ruapuna Raceway, Christchurch Super 440 | B276: Jack Le Brocq, MSR-005 | C276: 17/04/2026, Race 10 | D276: 5:36:37 PM, Run 1 | E276: Lap 4 | F276: 0.00098662037 | G276: 2.13 | H276: 2.73 | I276: 0.975 | J276: =H276*I276 -> 2.66175
A277: Ruapuna Raceway, Christchurch Super 440 | B277: Jack Le Brocq, MSR-005 | C277: 17/04/2026, Race 10 | D277: 5:36:37 PM, Run 1 | E277: Lap 5 | F277: 0.00098021991 | G277: 2.12 | H277: 2.73 | I277: 0.975 | J277: =H277*I277 -> 2.66175
A278: Ruapuna Raceway, Christchurch Super 440 | B278: Jack Le Brocq, MSR-005 | C278: 17/04/2026, Race 10 | D278: 5:36:37 PM, Run 1 | E278: Lap 6 | F278: 0.00098612269 | G278: 2.16 | H278: 2.78 | I278: 0.975 | J278: =H278*I278 -> 2.7105
A279: Ruapuna Raceway, Christchurch Super 440 | B279: Jack Le Brocq, MSR-005 | C279: 17/04/2026, Race 10 | D279: 5:36:37 PM, Run 1 | E279: Lap 7 | F279: 0.00097466435 | G279: 2.18 | H279: 2.81 | I279: 0.975 | J279: =H279*I279 -> 2.73975
A280: Ruapuna Raceway, Christchurch Super 440 | B280: Jack Le Brocq, MSR-005 | C280: 17/04/2026, Race 10 | D280: 5:36:37 PM, Run 1 | E280: Lap 8 | F280: 0.00097743056 | G280: 2.16 | H280: 2.77 | I280: 0.975 | J280: =H280*I280 -> 2.70075
A281: Ruapuna Raceway, Christchurch Super 440 | B281: Jack Le Brocq, MSR-005 | C281: 17/04/2026, Race 10 | D281: 5:36:37 PM, Run 1 | E281: Lap 9 | F281: 0.00097553241 | G281: 2.17 | H281: 2.8 | I281: 0.975 | J281: =H281*I281 -> 2.73
A282: Ruapuna Raceway, Christchurch Super 440 | B282: Jack Le Brocq, MSR-005 | C282: 17/04/2026, Race 10 | D282: 5:36:37 PM, Run 1 | E282: Lap 10 | F282: 0.00097716435 | G282: 2.2 | H282: 2.82 | I282: 0.975 | J282: =H282*I282 -> 2.7495
A283: Ruapuna Raceway, Christchurch Super 440 | B283: Jack Le Brocq, MSR-005 | C283: 17/04/2026, Race 10 | D283: 5:36:37 PM, Run 1 | E283: Lap 11 | F283: 0.00097523148 | G283: 2.2 | H283: 2.84 | I283: 0.975 | J283: =H283*I283 -> 2.769
A284: Ruapuna Raceway, Christchurch Super 440 | B284: Jack Le Brocq, MSR-005 | C284: 17/04/2026, Race 10 | D284: 5:36:37 PM, Run 1 | E284: Lap 12 | F284: 0.0009780787 | G284: 2.16 | H284: 2.79 | I284: 0.975 | J284: =H284*I284 -> 2.72025
A285: Ruapuna Raceway, Christchurch Super 440 | B285: Jack Le Brocq, MSR-005 | C285: 17/04/2026, Race 10 | D285: 5:36:37 PM, Run 1 | E285: Lap 13 | F285: 0.00097980324 | G285: 2.18 | H285: 2.8 | I285: 0.975 | J285: =H285*I285 -> 2.73
A286: Ruapuna Raceway, Christchurch Super 440 | B286: Jack Le Brocq, MSR-005 | C286: 17/04/2026, Race 10 | D286: 5:36:37 PM, Run 1 | E286: Lap 14 | F286: 0.00097796296 | G286: 2.2 | H286: 2.83 | I286: 0.975 | J286: =H286*I286 -> 2.75925
...

Sheet FC R11
B2: Fuel Consumption - 04 RUA
B4: Lap Count | C4: 61
B5: Out, Formation, In Multiple | C5: 1.5
B6: Usable Tank [l] | C6: 131.5
B7: Churn Size [l] | C7: 25 | AS7: GM | AT7: Ford | AU7: Toyota
B8: Churn Limit In Question | C8: 2
B9: Fuel Density (kg/L) | C9: =FuelDensity/1000 -> 0.789646 | AR9: Lap 1 | AS9: =#REF! -> #REF! | AT9: =#REF! -> #REF! | AU9: =#REF! -> #REF!
AR10: Lap 2 | AS10: =#REF! -> #REF! | AT10: =#REF! -> #REF! | AU10: =#REF! -> #REF!
B11: Fuel Density Calculator
B12: See 'Fuel Properties' Sheet
G15: Average | M15: Max | AS15: Lap 3 | AT15: =#REF! -> #REF! | AU15: =#REF! -> #REF! | AV15: =#REF! -> #REF!
B16: DASH | C16: Av Fuel Used [kg] | D16: Av Fuel Used [l] | E16: Max Fuel Used [l] | G16: Race Laps | H16: Out, F, In (1.5 Laps) | I16: Total Required | J16: Fuel Requied | K16: Churn Required | M16: Race Laps | N16: Out, F, In (1.5 Laps) | O16: Total Required | P16: Fuel Requied | Q16: Churn Required | AS16: Lap 4 | AT16: =#REF! -> #REF! | AU16: =#REF! -> #REF! | AV16: =#REF! -> #REF!
B17: GM | C17: {=_xlfn.LET(_xlpm.data, $W$43:$AB$62, _xlpm.filtered, _xlfn._xlws.FILTER(_xlpm.data, $W$43:$W$62='FC R11'!$B17), _xlpm.EOL, _xlfn.CHOOSECOLS(_xlpm.filtered,3), AVERAGE(_xlpm.EOL))} -> 2.1834118 | D17: {=_xlfn.LET(_xlpm.data, $W$43:$AB$62, _xlpm.filtered, _xlfn._xlws.FILTER(_xlpm.data, $W$43:$W$62='FC R11'!$B17), _xlpm.EOL, _xlfn.CHOOSECOLS(_xlpm.filtered,5), AVERAGE(_xlpm.EOL))} -> 2.7650514 | E17: {=_xlfn.LET(_xlpm.data, $W$43:$AB$62, _xlpm.filtered, _xlfn._xlws.FILTER(_xlpm.data, $W$43:$W$62='FC R11'!$B17), _xlpm.EOL, _xlfn.CHOOSECOLS(_xlpm.filtered,5), MAX(_xlpm.EOL))} -> 2.7961152 | G17: =D17*$C$4 -> 168.66813 | H17: =D17*$C$5 -> 4.1475771 | I17: =SUM(G17:H17) -> 172.81571 | J17: =I17-$C$6 -> 41.315711 | K17: =J17/$C$7 -> 1.6526285 | M17: =E17*$C$4 -> 170.56303 | N17: =E17*1.5 -> 4.1941728 | O17: =SUM(M17:N17) -> 174.7572 | P17: =O17-$C$6 -> 43.257199 | Q17: =P17/$C$7 -> 1.730288 | AS17: Lap 5 | AT17: =#REF! -> #REF! | AU17: =#REF! -> #REF! | AV17: =#REF! -> #REF!
B18: Ford | C18: {=_xlfn.LET(_xlpm.data, $W$43:$AB$62, _xlpm.filtered, _xlfn._xlws.FILTER(_xlpm.data, $W$43:$W$62='FC R11'!$B18), _xlpm.EOL, _xlfn.CHOOSECOLS(_xlpm.filtered,3), AVERAGE(_xlpm.EOL))} -> 2.1768558 | D18: {=_xlfn.LET(_xlpm.data, $W$43:$AB$62, _xlpm.filtered, _xlfn._xlws.FILTER(_xlpm.data, $W$43:$W$62='FC R11'!$B18), _xlpm.EOL, _xlfn.CHOOSECOLS(_xlpm.filtered,5), AVERAGE(_xlpm.EOL))} -> 2.756749 | E18: {=_xlfn.LET(_xlpm.data, $W$43:$AB$62, _xlpm.filtered, _xlfn._xlws.FILTER(_xlpm.data, $W$43:$W$62='FC R11'!$B18), _xlpm.EOL, _xlfn.CHOOSECOLS(_xlpm.filtered,5), MAX(_xlpm.EOL))} -> 2.8058143 | G18: =D18*$C$4 -> 168.16169 | H18: =D18*$C$5 -> 4.1351234 | I18: =SUM(G18:H18) -> 172.29681 | J18: =I18-$C$6 -> 40.796809 | K18: =J18/$C$7 -> 1.6318724 | M18: =E18*$C$4 -> 171.15467 | N18: =E18*1.5 -> 4.2087214 | O18: =SUM(M18:N18) -> 175.36339 | P18: =O18-$C$6 -> 43.863391 | Q18: =P18/$C$7 -> 1.7545356 | AS18: Lap 6 | AT18: =#REF! -> #REF! | AU18: =#REF! -> #REF! | AV18: =#REF! -> #REF!
B19: Toyota | C19: {=_xlfn.LET(_xlpm.data, $W$43:$AB$62, _xlpm.filtered, _xlfn._xlws.FILTER(_xlpm.data, $W$43:$W$62='FC R11'!$B19), _xlpm.EOL, _xlfn.CHOOSECOLS(_xlpm.filtered,3), AVERAGE(_xlpm.EOL))} -> 2.1641355 | D19: {=_xlfn.LET(_xlpm.data, $W$43:$AB$62, _xlpm.filtered, _xlfn._xlws.FILTER(_xlpm.data, $W$43:$W$62='FC R11'!$B19), _xlpm.EOL, _xlfn.CHOOSECOLS(_xlpm.filtered,5), AVERAGE(_xlpm.EOL))} -> 2.7406401 | E19: {=_xlfn.LET(_xlpm.data, $W$43:$AB$62, _xlpm.filtered, _xlfn._xlws.FILTER(_xlpm.data, $W$43:$W$62='FC R11'!$B19), _xlpm.EOL, _xlfn.CHOOSECOLS(_xlpm.filtered,5), MAX(_xlpm.EOL))} -> 2.7763744 | G19: =D19*$C$4 -> 167.17904 | H19: =D19*$C$5 -> 4.1109601 | I19: =SUM(G19:H19) -> 171.29 | J19: =I19-$C$6 -> 39.790005 | K19: =J19/$C$7 -> 1.5916002 | M19: =E19*$C$4 -> 169.35884 | N19: =E19*1.5 -> 4.1645616 | O19: =SUM(M19:N19) -> 173.5234 | P19: =O19-$C$6 -> 42.0234 | Q19: =P19/$C$7 -> 1.680936 | AS19: Lap 7 | AT19: =#REF! -> #REF! | AU19: =#REF! -> #REF! | AV19: =#REF! -> #REF!
B20: * Dash Calculates Fuel Used in Kg, Fuel Error is included in the number | AS20: Lap 8 | AT20: =#REF! -> #REF! | AU20: =#REF! -> #REF! | AV20: =#REF! -> #REF!
AS21: Lap 9 | AT21: =#REF! -> #REF! | AU21: =#REF! -> #REF! | AV21: =#REF! -> #REF!
G28: Average | M28: Max
B29: ECU | D29: Av Fuel Used [l] | E29: Max Fuel Used [l] | G29: Race Laps | H29: Out, F, In (1.5 Laps) | I29: Total Required | J29: Fuel Requied | K29: Churn Required | M29: Race Laps | N29: Out, F, In (1.5 Laps) | O29: Total Required | P29: Fuel Requied | Q29: Churn Required
B30: GM | D30: {=_xlfn.LET(_xlpm.data, $W$43:$AB$62, _xlpm.filtered, _xlfn._xlws.FILTER(_xlpm.data, $W$43:$W$62='FC R11'!$B30), _xlpm.EOL, _xlfn.CHOOSECOLS(_xlpm.filtered,6), AVERAGE(_xlpm.EOL))} -> 2.7725082 | E30: {=_xlfn.LET(_xlpm.data, $W$43:$AB$62, _xlpm.filtered, _xlfn._xlws.FILTER(_xlpm.data, $W$43:$W$62='FC R11'!$B30), _xlpm.EOL, _xlfn.CHOOSECOLS(_xlpm.filtered,6), MAX(_xlpm.EOL))} -> 2.8242118 | G30: =D30*$C$4 -> 169.123 | H30: =D30*$C$5 -> 4.1587624 | I30: =SUM(G30:H30) -> 173.28176 | J30: =I30-$C$6 -> 41.781765 | K30: =J30/$C$7 -> 1.6712706 | M30: =E30*$C$4 -> 172.27692 | N30: =E30*1.5 -> 4.2363176 | O30: =SUM(M30:N30) -> 176.51324 | P30: =O30-$C$6 -> 45.013235 | Q30: =P30/$C$7 -> 1.8005294
B31: Ford | D31: {=_xlfn.LET(_xlpm.data, $W$43:$AB$62, _xlpm.filtered, _xlfn._xlws.FILTER(_xlpm.data, $W$43:$W$62='FC R11'!$B31), _xlpm.EOL, _xlfn.CHOOSECOLS(_xlpm.filtered,6), AVERAGE(_xlpm.EOL))} -> 2.8133476 | E31: {=_xlfn.LET(_xlpm.data, $W$43:$AB$62, _xlpm.filtered, _xlfn._xlws.FILTER(_xlpm.data, $W$43:$W$62='FC R11'!$B31), _xlpm.EOL, _xlfn.CHOOSECOLS(_xlpm.filtered,6), MAX(_xlpm.EOL))} -> 2.922686 | G31: =D31*$C$4 -> 171.61421 | H31: =D31*$C$5 -> 4.2200214 | I31: =SUM(G31:H31) -> 175.83423 | J31: =I31-$C$6 -> 44.334227 | K31: =J31/$C$7 -> 1.7733691 | M31: =E31*$C$4 -> 178.28385 | N31: =E31*1.5 -> 4.384029 | O31: =SUM(M31:N31) -> 182.66788 | P31: =O31-$C$6 -> 51.167875 | Q31: =P31/$C$7 -> 2.046715
B32: Toyota | D32: {=_xlfn.LET(_xlpm.data, $W$43:$AB$62, _xlpm.filtered, _xlfn._xlws.FILTER(_xlpm.data, $W$43:$W$62='FC R11'!$B32), _xlpm.EOL, _xlfn.CHOOSECOLS(_xlpm.filtered,6), AVERAGE(_xlpm.EOL))} -> 2.8049485 | E32: {=_xlfn.LET(_xlpm.data, $W$43:$AB$62, _xlpm.filtered, _xlfn._xlws.FILTER(_xlpm.data, $W$43:$W$62='FC R11'!$B32), _xlpm.EOL, _xlfn.CHOOSECOLS(_xlpm.filtered,6), MAX(_xlpm.EOL))} -> 2.8864206 | G32: =D32*$C$4 -> 171.10186 | H32: =D32*$C$5 -> 4.2074228 | I32: =SUM(G32:H32) -> 175.30928 | J32: =I32-$C$6 -> 43.809284 | K32: =J32/$C$7 -> 1.7523714 | M32: =E32*$C$4 -> 176.07166 | N32: =E32*1.5 -> 4.3296309 | O32: =SUM(M32:N32) -> 180.40129 | P32: =O32-$C$6 -> 48.901287 | Q32: =P32/$C$7 -> 1.9560515
B33: * ECU Sends Fuel Used in l, then combined with Fuel Error.
B34: * PROBLEM: Fuel Error is used to calibrate the Fuel Use from the Dash, no guarantee it is the same with the ECU
W42: Make | X42: Driver | Y42: Fuel Used Dash Average [kg] | AA42: Fuel Used Dash Average [l] | AB42: Fuel Used ECU Average [l] | AD42: Error
W43: Toyota | X43: {=_xlfn._xlws.FILTER(_xlfn.UNIQUE('DUMP R11'!B:B),_xlfn.UNIQUE('DUMP R11'!B:B)<>0)} -> Jack Le Brocq, MSR-005 | Y43: {=_xlfn.LET(_xlpm.data, 'DUMP R11'!$A$3:$J$10000, _xlpm.filtered, _xlfn._xlws.FILTER(_xlpm.data,'DUMP R11'!$B$3:$B$10000=$X43), _xlpm.EOL_Dash, _xlfn.CHOOSECOLS(_xlpm.filtered,7), AVERAGE(_xlpm.EOL_Dash))} -> 2.1758824 | AA43: =Y43/$C$9 -> 2.7555162 | AB43: {=_xlfn.LET(_xlpm.data, 'DUMP R11'!$A$3:$J$10000, _xlpm.filtered, _xlfn._xlws.FILTER(_xlpm.data,'DUMP R11'!$B$3:$B$10000=$X43), _xlpm.EOL_w_Error, _xlfn.CHOOSECOLS(_xlpm.filtered,10), AVERAGE(_xlpm.EOL_w_Error))} -> 2.7295309 | AD43: =1-AB43/AA43 -> 0.0094302938
W44: Ford | X44: Thomas Randle, TR26 | Y44: {=_xlfn.LET(_xlpm.data, 'DUMP R11'!$A$3:$J$10000, _xlpm.filtered, _xlfn._xlws.FILTER(_xlpm.data,'DUMP R11'!$B$3:$B$10000=$X44), _xlpm.EOL_Dash, _xlfn.CHOOSECOLS(_xlpm.filtered,7), AVERAGE(_xlpm.EOL_Dash))} -> 2.1467647 | AA44: =Y44/$C$9 -> 2.7186419 | AB44: {=_xlfn.LET(_xlpm.data, 'DUMP R11'!$A$3:$J$10000, _xlpm.filtered, _xlfn._xlws.FILTER(_xlpm.data,'DUMP R11'!$B$3:$B$10000=X44), _xlpm.EOL_w_Error, _xlfn.CHOOSECOLS(_xlpm.filtered,10), AVERAGE(_xlpm.EOL_w_Error))} -> 2.7847059 | AD44: =1-AB44/AA44 -> -0.02430036
W45: Ford | X45: Rylan Gray, DJRS08-MR | Y45: {=_xlfn.LET(_xlpm.data, 'DUMP R11'!$A$3:$J$10000, _xlpm.filtered, _xlfn._xlws.FILTER(_xlpm.data,'DUMP R11'!$B$3:$B$10000=$X45), _xlpm.EOL_Dash, _xlfn.CHOOSECOLS(_xlpm.filtered,7), AVERAGE(_xlpm.EOL_Dash))} -> 2.1167647 | AA45: =Y45/$C$9 -> 2.6806502 | AB45: {=_xlfn.LET(_xlpm.data, 'DUMP R11'!$A$3:$J$10000, _xlpm.filtered, _xlfn._xlws.FILTER(_xlpm.data,'DUMP R11'!$B$3:$B$10000=X45), _xlpm.EOL_w_Error, _xlfn.CHOOSECOLS(_xlpm.filtered,10), AVERAGE(_xlpm.EOL_w_Error))} -> 2.7461765 | AD45: =1-AB45/AA45 -> -0.024444171
W46: Ford | X46: Cam Waters, TR28 | Y46: {=_xlfn.LET(_xlpm.data, 'DUMP R11'!$A$3:$J$10000, _xlpm.filtered, _xlfn._xlws.FILTER(_xlpm.data,'DUMP R11'!$B$3:$B$10000=$X46), _xlpm.EOL_Dash, _xlfn.CHOOSECOLS(_xlpm.filtered,7), AVERAGE(_xlpm.EOL_Dash))} -> 2.2029412 | AA46: =Y46/$C$9 -> 2.7897832 | AB46: {=_xlfn.LET(_xlpm.data, 'DUMP R11'!$A$3:$J$10000, _xlpm.filtered, _xlfn._xlws.FILTER(_xlpm.data,'DUMP R11'!$B$3:$B$10000=X46), _xlpm.EOL_w_Error, _xlfn.CHOOSECOLS(_xlpm.filtered,10), AVERAGE(_xlpm.EOL_w_Error))} -> 2.8597929 | AD46: =1-AB46/AA46 -> -0.025095032
W47: GM | X47: Anton De Pasquale, T18-004 | Y47: {=_xlfn.LET(_xlpm.data, 'DUMP R11'!$A$3:$J$10000, _xlpm.filtered, _xlfn._xlws.FILTER(_xlpm.data,'DUMP R11'!$B$3:$B$10000=$X47), _xlpm.EOL_Dash, _xlfn.CHOOSECOLS(_xlpm.filtered,7), AVERAGE(_xlpm.EOL_Dash))} -> 2.2035294 | AA47: =Y47/$C$9 -> 2.7905282 | AB47: {=_xlfn.LET(_xlpm.data, 'DUMP R11'!$A$3:$J$10000, _xlpm.filtered, _xlfn._xlws.FILTER(_xlpm.data,'DUMP R11'!$B$3:$B$10000=X47), _xlpm.EOL_w_Error, _xlfn.CHOOSECOLS(_xlpm.filtered,10), AVERAGE(_xlpm.EOL_w_Error))} -> 2.7639294 | AD47: =1-AB47/AA47 -> 0.0095318026
W48: Ford | X48: Zach Bates, MSR-006 | Y48: {=_xlfn.LET(_xlpm.data, 'DUMP R11'!$A$3:$J$10000, _xlpm.filtered, _xlfn._xlws.FILTER(_xlpm.data,'DUMP R11'!$B$3:$B$10000=$X48), _xlpm.EOL_Dash, _xlfn.CHOOSECOLS(_xlpm.filtered,7), AVERAGE(_xlpm.EOL_Dash))} -> 2.1829412 | AA48: =Y48/$C$9 -> 2.7644554 | AB48: {=_xlfn.LET(_xlpm.data, 'DUMP R11'!$A$3:$J$10000, _xlpm.filtered, _xlfn._xlws.FILTER(_xlpm.data,'DUMP R11'!$B$3:$B$10000=X48), _xlpm.EOL_w_Error, _xlfn.CHOOSECOLS(_xlpm.filtered,10), AVERAGE(_xlpm.EOL_w_Error))} -> 2.7280976 | AD48: =1-AB48/AA48 -> 0.013151881
W49: GM | X49: David Reynolds, T18-003 | Y49: {=_xlfn.LET(_xlpm.data, 'DUMP R11'!$A$3:$J$10000, _xlpm.filtered, _xlfn._xlws.FILTER(_xlpm.data,'DUMP R11'!$B$3:$B$10000=$X49), _xlpm.EOL_Dash, _xlfn.CHOOSECOLS(_xlpm.filtered,7), AVERAGE(_xlpm.EOL_Dash))} -> 2.2079412 | AA49: =Y49/$C$9 -> 2.7961152 | AB49: {=_xlfn.LET(_xlpm.data, 'DUMP R11'!$A$3:$J$10000, _xlpm.filtered, _xlfn._xlws.FILTER(_xlpm.data,'DUMP R11'!$B$3:$B$10000=X49), _xlpm.EOL_w_Error, _xlfn.CHOOSECOLS(_xlpm.filtered,10), AVERAGE(_xlpm.EOL_w_Error))} -> 2.7632647 | AD49: =1-AB49/AA49 -> 0.011748617
W50: Ford | X50: Broc Feeney, 888A-072 | Y50: {=_xlfn.LET(_xlpm.data, 'DUMP R11'!$A$3:$J$10000, _xlpm.filtered, _xlfn._xlws.FILTER(_xlpm.data,'DUMP R11'!$B$3:$B$10000=$X50), _xlpm.EOL_Dash, _xlfn.CHOOSECOLS(_xlpm.filtered,7), AVERAGE(_xlpm.EOL_Dash))} -> 2.2011765 | AA50: =Y50/$C$9 -> 2.7875484 | AB50: {=_xlfn.LET(_xlpm.data, 'DUMP R11'!$A$3:$J$10000, _xlpm.filtered, _xlfn._xlws.FILTER(_xlpm.data,'DUMP R11'!$B$3:$B$10000=X50), _xlpm.EOL_w_Error, _xlfn.CHOOSECOLS(_xlpm.filtered,10), AVERAGE(_xlpm.EOL_w_Error))} -> 2.8499929 | AD50: =1-AB50/AA50 -> -0.022401228
W51: GM | X51: Jayden Ojeda, 888A-064 | Y51: {=_xlfn.LET(_xlpm.data, 'DUMP R11'!$A$3:$J$10000, _xlpm.filtered, _xlfn._xlws.FILTER(_xlpm.data,'DUMP R11'!$B$3:$B$10000=$X51), _xlpm.EOL_Dash, _xlfn.CHOOSECOLS(_xlpm.filtered,7), AVERAGE(_xlpm.EOL_Dash))} -> 2.1691176 | AA51: =Y51/$C$9 -> 2.7469495 | AB51: {=_xlfn.LET(_xlpm.data, 'DUMP R11'!$A$3:$J$10000, _xlpm.filtered, _xlfn._xlws.FILTER(_xlpm.data,'DUMP R11'!$B$3:$B$10000=X51), _xlpm.EOL_w_Error, _xlfn.CHOOSECOLS(_xlpm.filtered,10), AVERAGE(_xlpm.EOL_w_Error))} -> 2.7107868 | AD51: =1-AB51/AA51 -> 0.013164672
W52: Ford | X52: Declan Fraser, 888A-062 | Y52: {=_xlfn.LET(_xlpm.data, 'DUMP R11'!$A$3:$J$10000, _xlpm.filtered, _xlfn._xlws.FILTER(_xlpm.data,'DUMP R11'!$B$3:$B$10000=$X52), _xlpm.EOL_Dash, _xlfn.CHOOSECOLS(_xlpm.filtered,7), AVERAGE(_xlpm.EOL_Dash))} -> 2.2106061 | AA52: =Y52/$C$9 -> 2.79949 | AB52: {=_xlfn.LET(_xlpm.data, 'DUMP R11'!$A$3:$J$10000, _xlpm.filtered, _xlfn._xlws.FILTER(_xlpm.data,'DUMP R11'!$B$3:$B$10000=X52), _xlpm.EOL_w_Error, _xlfn.CHOOSECOLS(_xlpm.filtered,10), AVERAGE(_xlpm.EOL_w_Error))} -> 2.7732364 | AD52: =1-AB52/AA52 -> 0.0093779979
W53: Ford | X53: Jackson Walls, 888A-074 | Y53: {=_xlfn.LET(_xlpm.data, 'DUMP R11'!$A$3:$J$10000, _xlpm.filtered, _xlfn._xlws.FILTER(_xlpm.data,'DUMP R11'!$B$3:$B$10000=$X53), _xlpm.EOL_Dash, _xlfn.CHOOSECOLS(_xlpm.filtered,7), AVERAGE(_xlpm.EOL_Dash))} -> 2.1097059 | AA53: =Y53/$C$9 -> 2.671711 | AB53: {=_xlfn.LET(_xlpm.data, 'DUMP R11'!$A$3:$J$10000, _xlpm.filtered, _xlfn._xlws.FILTER(_xlpm.data,'DUMP R11'!$B$3:$B$10000=X53), _xlpm.EOL_w_Error, _xlfn.CHOOSECOLS(_xlpm.filtered,10), AVERAGE(_xlpm.EOL_w_Error))} -> 2.73632 | AD53: =1-AB53/AA53 -> -0.024182641
W54: Toyota | X54: Chaz Mostert, WR-032 | Y54: {=_xlfn.LET(_xlpm.data, 'DUMP R11'!$A$3:$J$10000, _xlpm.filtered, _xlfn._xlws.FILTER(_xlpm.data,'DUMP R11'!$B$3:$B$10000=$X54), _xlpm.EOL_Dash, _xlfn.CHOOSECOLS(_xlpm.filtered,7), AVERAGE(_xlpm.EOL_Dash))} -> 2.1524242 | AA54: =Y54/$C$9 -> 2.7258091 | AB54: {=_xlfn.LET(_xlpm.data, 'DUMP R11'!$A$3:$J$10000, _xlpm.filtered, _xlfn._xlws.FILTER(_xlpm.data,'DUMP R11'!$B$3:$B$10000=X54), _xlpm.EOL_w_Error, _xlfn.CHOOSECOLS(_xlpm.filtered,10), AVERAGE(_xlpm.EOL_w_Error))} -> 2.8373721 | AD54: =1-AB54/AA54 -> -0.040928411
W55: Ford | X55: Aaron Cameron, BRT-001 | Y55: {=_xlfn.LET(_xlpm.data, 'DUMP R11'!$A$3:$J$10000, _xlpm.filtered, _xlfn._xlws.FILTER(_xlpm.data,'DUMP R11'!$B$3:$B$10000=$X55), _xlpm.EOL_Dash, _xlfn.CHOOSECOLS(_xlpm.filtered,7), AVERAGE(_xlpm.EOL_Dash))} -> 2.165 | AA55: =Y55/$C$9 -> 2.7417349 | AB55: {=_xlfn.LET(_xlpm.data, 'DUMP R11'!$A$3:$J$10000, _xlpm.filtered, _xlfn._xlws.FILTER(_xlpm.data,'DUMP R11'!$B$3:$B$10000=X55), _xlpm.EOL_w_Error, _xlfn.CHOOSECOLS(_xlpm.filtered,10), AVERAGE(_xlpm.EOL_w_Error))} -> 2.8024871 | AD55: =1-AB55/AA55 -> -0.022158289
... W62: Ford | X62: Cam Hill, BJR020 | Y62: {=_xlfn.LET(_xlpm.data, 'DUMP R11'!$A$3:$J$10000, _xlpm.filtered, _xlfn._xlws.FILTER(_xlpm.data,'DUMP R11'!$B$3:$B$10000=$X62), _xlpm.EOL_Dash, _xlfn.CHOOSECOLS(_xlpm.filtered,7), AVERAGE(_xlpm.EOL_Dash))} -> 2.2156 | AA62: =Y62/$C$9 -> 2.8058143 | AB62: {=_xlfn.LET(_xlpm.data, 'DUMP R11'!$A$3:$J$10000, _xlpm.filtered, _xlfn._xlws.FILTER(_xlpm.data,'DUMP R11'!$B$3:$B$10000=X62), _xlpm.EOL_w_Error, _xlfn.CHOOSECOLS(_xlpm.filtered,10), AVERAGE(_xlpm.EOL_w_Error))} -> 2.922686 | AD62: =1-AB62/AA62 -> -0.041653416
X63: Andre Heimgartner, BJR019
...

Sheet DUMP R11
A1: Fuel Behaviour | G1: Fuel Used kg EOL [kg] | H1: Fuel Used EOL [l] | I1: Fuel Error | J1: Fuel Used ECU [l]
G2: Avg | H2: Avg | I2: Avg
A3: Ruapuna Raceway, Christchurch Super 440 | B3: Jack Le Brocq, MSR-005 | C3: 18/04/2026, Race 11 | D3: 1:44:48 PM, Run 1 | E3: Lap 3 | F3: 0.0009972338 | G3: 2.06 | H3: 2.67 | I3: 0.965 | J3: =H3*I3 -> 2.57655
A4: Ruapuna Raceway, Christchurch Super 440 | B4: Jack Le Brocq, MSR-005 | C4: 18/04/2026, Race 11 | D4: 1:44:48 PM, Run 1 | E4: Lap 4 | F4: 0.00097789352 | G4: 2.08 | H4: 2.69 | I4: 0.965 | J4: =H4*I4 -> 2.59585
A5: Ruapuna Raceway, Christchurch Super 440 | B5: Jack Le Brocq, MSR-005 | C5: 18/04/2026, Race 11 | D5: 1:44:48 PM, Run 1 | E5: Lap 5 | F5: 0.00099225694 | G5: 2.06 | H5: 2.68 | I5: 0.965 | J5: =H5*I5 -> 2.5862
A6: Ruapuna Raceway, Christchurch Super 440 | B6: Jack Le Brocq, MSR-005 | C6: 18/04/2026, Race 11 | D6: 1:44:48 PM, Run 1 | E6: Lap 6 | F6: 0.00097555556 | G6: 2.1 | H6: 2.74 | I6: 0.965 | J6: =H6*I6 -> 2.6441
A7: Ruapuna Raceway, Christchurch Super 440 | B7: Jack Le Brocq, MSR-005 | C7: 18/04/2026, Race 11 | D7: 1:44:48 PM, Run 1 | E7: Lap 7 | F7: 0.00097498843 | G7: 2.1 | H7: 2.72 | I7: 0.965 | J7: =H7*I7 -> 2.6248
A8: Ruapuna Raceway, Christchurch Super 440 | B8: Jack Le Brocq, MSR-005 | C8: 18/04/2026, Race 11 | D8: 1:44:48 PM, Run 1 | E8: Lap 8 | F8: 0.00097939815 | G8: 2.09 | H8: 2.72 | I8: 0.965 | J8: =H8*I8 -> 2.6248
A9: Ruapuna Raceway, Christchurch Super 440 | B9: Jack Le Brocq, MSR-005 | C9: 18/04/2026, Race 11 | D9: 1:44:48 PM, Run 1 | E9: Lap 9 | F9: 0.00097883102 | G9: 2.14 | H9: 2.77 | I9: 0.965 | J9: =H9*I9 -> 2.67305
A10: Ruapuna Raceway, Christchurch Super 440 | B10: Jack Le Brocq, MSR-005 | C10: 18/04/2026, Race 11 | D10: 1:44:48 PM, Run 1 | E10: Lap 10 | F10: 0.00097726852 | G10: 2.14 | H10: 2.78 | I10: 0.965 | J10: =H10*I10 -> 2.6827
A11: Ruapuna Raceway, Christchurch Super 440 | B11: Jack Le Brocq, MSR-005 | C11: 18/04/2026, Race 11 | D11: 1:44:48 PM, Run 1 | E11: Lap 12 | F11: 0.00096320602 | G11: 2.25 | H11: 2.92 | I11: 0.965 | J11: =H11*I11 -> 2.8178
A12: Ruapuna Raceway, Christchurch Super 440 | B12: Jack Le Brocq, MSR-005 | C12: 18/04/2026, Race 11 | D12: 1:44:48 PM, Run 1 | E12: Lap 13 | F12: 0.00096224537 | G12: 2.24 | H12: 2.92 | I12: 0.965 | J12: =H12*I12 -> 2.8178
A13: Ruapuna Raceway, Christchurch Super 440 | B13: Jack Le Brocq, MSR-005 | C13: 18/04/2026, Race 11 | D13: 1:44:48 PM, Run 1 | E13: Lap 14 | F13: 0.00096289352 | G13: 2.25 | H13: 2.93 | I13: 0.965 | J13: =H13*I13 -> 2.82745
A14: Ruapuna Raceway, Christchurch Super 440 | B14: Jack Le Brocq, MSR-005 | C14: 18/04/2026, Race 11 | D14: 1:44:48 PM, Run 1 | E14: Lap 15 | F14: 0.00096372685 | G14: 2.26 | H14: 2.92 | I14: 0.965 | J14: =H14*I14 -> 2.8178
... A646: Ruapuna, 2026 Christchurch Super 440 | B646: Matt Payne, GR02 | C646: 18/04/2026, Race 11 | D646: 1:46:10 PM, Runs all | E646: Lap 36 | F646: 0.00096916667 | G646: 2.14 | H646: 2.82 | I646: 0.99 | J646: =H646*I646 -> 2.7918
A647: Ruapuna Raceway, Christchurch Super440 | B647: Cam Hill, BJR020 | C647: 18/04/2026, Race 11 | D647: 0.57449074 | E647: Lap 3 | F647: 0.00098700231 | G647: 2.12 | H647: 3.31 | I647: 0.845 | J647: =H647*I647 -> 2.79695
A648: Ruapuna Raceway, Christchurch Super440 | B648: Cam Hill, BJR020 | C648: 18/04/2026, Race 11 | D648: 0.57449074 | E648: Lap 4 | F648: 0.00099762731 | G648: 2.14 | H648: 3.34 | I648: 0.845 | J648: =H648*I648 -> 2.8223
A649: Ruapuna Raceway, Christchurch Super440 | B649: Cam Hill, BJR020 | C649: 18/04/2026, Race 11 | D649: 0.57449074 | E649: Lap 6 | F649: 0.00097939815 | G649: 2.27 | H649: 3.54 | I649: 0.845 | J649: =H649*I649 -> 2.9913
A650: Ruapuna Raceway, Christchurch Super440 | B650: Cam Hill, BJR020 | C650: 18/04/2026, Race 11 | D650: 0.57449074 | E650: Lap 7 | F650: 0.00097701389 | G650: 2.27 | H650: 3.56 | I650: 0.845 | J650: =H650*I650 -> 3.0082
A651: Ruapuna Raceway, Christchurch Super440 | B651: Cam Hill, BJR020 | C651: 18/04/2026, Race 11 | D651: 0.57449074 | E651: Lap 8 | F651: 0.0009762037 | G651: 2.26 | H651: 3.54 | I651: 0.845 | J651: =H651*I651 -> 2.9913
A652: Ruapuna Raceway, Christchurch Super440 | B652: Cam Hill, BJR020 | C652: 18/04/2026, Race 11 | D652: 0.57449074 | E652: Lap 9 | F652: 0.00097748843 | G652: 2.25 | H652: 3.5 | I652: 0.845 | J652: =H652*I652 -> 2.9575
A653: Ruapuna Raceway, Christchurch Super440 | B653: Cam Hill, BJR020 | C653: 18/04/2026, Race 11 | D653: 0.57449074 | E653: Lap 10 | F653: 0.00097741898 | G653: 2.25 | H653: 3.5 | I653: 0.845 | J653: =H653*I653 -> 2.9575
A654: Ruapuna Raceway, Christchurch Super440 | B654: Cam Hill, BJR020 | C654: 18/04/2026, Race 11 | D654: 0.57449074 | E654: Lap 11 | F654: 0.00097980324 | G654: 2.25 | H654: 3.5 | I654: 0.845 | J654: =H654*I654 -> 2.9575
A655: Ruapuna Raceway, Christchurch Super440 | B655: Cam Hill, BJR020 | C655: 18/04/2026, Race 11 | D655: 0.57449074 | E655: Lap 12 | F655: 0.00097828704 | G655: 2.25 | H655: 3.5 | I655: 0.845 | J655: =H655*I655 -> 2.9575
A656: Ruapuna Raceway, Christchurch Super440 | B656: Cam Hill, BJR020 | C656: 18/04/2026, Race 11 | D656: 0.57449074 | E656: Lap 13 | F656: 0.00098225694 | G656: 2.25 | H656: 3.51 | I656: 0.845 | J656: =H656*I656 -> 2.96595
A657: Ruapuna Raceway, Christchurch Super440 | B657: Cam Hill, BJR020 | C657: 18/04/2026, Race 11 | D657: 0.57449074 | E657: Lap 14 | F657: 0.00097868056 | G657: 2.25 | H657: 3.49 | I657: 0.845 | J657: =H657*I657 -> 2.94905
A658: Ruapuna Raceway, Christchurch Super440 | B658: Cam Hill, BJR020 | C658: 18/04/2026, Race 11 | D658: 0.57449074 | E658: Lap 15 | F658: 0.00098106481 | G658: 2.24 | H658: 3.48 | I658: 0.845 | J658: =H658*I658 -> 2.9406
... A697: Ruapuna Raceway, Christchurch Super440 | B697: Andre Heimgartner, BJR019 | C697: 18/04/2026, Race 11 | D697: 0.57486111 | E697: Lap 30 | F697: 0.00099537037 | G697: 2.11 | H697: 3.28 | I697: 0.848 | J697: =H697*I697 -> 2.78144
A698: Ruapuna, 2026 Christchurch Super440 | B698: Kai Allen, GR-03 | C698: 18/04/2026, Race 11 | D698: 2:03:03 PM, Runs all | E698: Lap 2 | F698: 0.0010106829 | G698: 2.22 | H698: 2.9 | I698: 0.995 | J698: =H698*I698 -> 2.8855
A699: Ruapuna, 2026 Christchurch Super440 | B699: Kai Allen, GR-03 | C699: 18/04/2026, Race 11 | D699: 2:03:03 PM, Runs all | E699: Lap 3 | F699: 0.00096262731 | G699: 2.14 | H699: 2.79 | I699: 0.995 | J699: =H699*I699 -> 2.77605
A700: Ruapuna, 2026 Christchurch Super440 | B700: Kai Allen, GR-03 | C700: 18/04/2026, Race 11 | D700: 2:03:03 PM, Runs all | E700: Lap 4 | F700: 0.00096408565 | G700: 2.12 | H700: 2.77 | I700: 0.995 | J700: =H700*I700 -> 2.75615
A701: Ruapuna, 2026 Christchurch Super440 | B701: Kai Allen, GR-03 | C701: 18/04/2026, Race 11 | D701: 2:03:03 PM, Runs all | E701: Lap 5 | F701: 0.00096511574 | G701: 2.17 | H701: 2.81 | I701: 0.995 | J701: =H701*I701 -> 2.79595
A702: Ruapuna, 2026 Christchurch Super440 | B702: Kai Allen, GR-03 | C702: 18/04/2026, Race 11 | D702: 2:03:03 PM, Runs all | E702: Lap 6 | F702: 0.00096431713 | G702: 2.15 | H702: 2.8 | I702: 0.995 | J702: =H702*I702 -> 2.786
A703: Ruapuna, 2026 Christchurch Super440 | B703: Kai Allen, GR-03 | C703: 18/04/2026, Race 11 | D703: 2:03:03 PM, Runs all | E703: Lap 7 | F703: 0.00096607639 | G703: 2.17 | H703: 2.82 | I703: 0.995 | J703: =H703*I703 -> 2.8059
A704: Ruapuna, 2026 Christchurch Super440 | B704: Kai Allen, GR-03 | C704: 18/04/2026, Race 11 | D704: 2:03:03 PM, Runs all | E704: Lap 8 | F704: 0.00096707176 | G704: 2.15 | H704: 2.81 | I704: 0.995 | J704: =H704*I704 -> 2.79595
A705: Ruapuna, 2026 Christchurch Super440 | B705: Kai Allen, GR-03 | C705: 18/04/2026, Race 11 | D705: 2:03:03 PM, Runs all | E705: Lap 9 | F705: 0.00096703704 | G705: 2.17 | H705: 2.82 | I705: 0.995 | J705: =H705*I705 -> 2.8059
A706: Ruapuna, 2026 Christchurch Super440 | B706: Kai Allen, GR-03 | C706: 18/04/2026, Race 11 | D706: 2:03:03 PM, Runs all | E706: Lap 10 | F706: 0.0009743287 | G706: 2.14 | H706: 2.79 | I706: 0.995 | J706: =H706*I706 -> 2.77605
A707: Ruapuna, 2026 Christchurch Super440 | B707: Kai Allen, GR-03 | C707: 18/04/2026, Race 11 | D707: 2:03:03 PM, Runs all | E707: Lap 11 | F707: 0.00097398148 | G707: 2.11 | H707: 2.74 | I707: 0.995 | J707: =H707*I707 -> 2.7263
A708: Ruapuna, 2026 Christchurch Super440 | B708: Kai Allen, GR-03 | C708: 18/04/2026, Race 11 | D708: 2:03:03 PM, Runs all | E708: Lap 12 | F708: 0.00097038194 | G708: 2.13 | H708: 2.79 | I708: 0.995 | J708: =H708*I708 -> 2.77605
A709: Ruapuna, 2026 Christchurch Super440 | B709: Kai Allen, GR-03 | C709: 18/04/2026, Race 11 | D709: 2:03:03 PM, Runs all | E709: Lap 13 | F709: 0.00097085648 | G709: 2.14 | H709: 2.8 | I709: 0.995 | J709: =H709*I709 -> 2.786
...

Sheet FC R12
B2: Fuel Consumption - 04 RUA
B4: Lap Count | C4: 61
B5: Out, Formation, In Multiple | C5: 1.5
B6: Usable Tank [l] | C6: 131.5
B7: Churn Size [l] | C7: 25 | AS7: GM | AT7: Ford | AU7: Toyota
B8: Churn Limit In Question | C8: 2
B9: Fuel Density (kg/L) | C9: =FuelDensity/1000 -> 0.789646 | AR9: Lap 1 | AS9: =#REF! -> #REF! | AT9: =#REF! -> #REF! | AU9: =#REF! -> #REF!
AR10: Lap 2 | AS10: =#REF! -> #REF! | AT10: =#REF! -> #REF! | AU10: =#REF! -> #REF!
B11: Fuel Density Calculator
B12: See 'Fuel Properties' Sheet
G15: Average | M15: Max | AS15: Lap 3 | AT15: =#REF! -> #REF! | AU15: =#REF! -> #REF! | AV15: =#REF! -> #REF!
B16: DASH | C16: Av Fuel Used [kg] | D16: Av Fuel Used [l] | E16: Max Fuel Used [l] | G16: Race Laps | H16: Out, F, In (1.5 Laps) | I16: Total Required | J16: Fuel Requied | K16: Churn Required | M16: Race Laps | N16: Out, F, In (1.5 Laps) | O16: Total Required | P16: Fuel Requied | Q16: Churn Required | AS16: Lap 4 | AT16: =#REF! -> #REF! | AU16: =#REF! -> #REF! | AV16: =#REF! -> #REF!
B17: GM | C17: {=_xlfn.LET(_xlpm.data, $W$43:$AB$62, _xlpm.filtered, _xlfn._xlws.FILTER(_xlpm.data, $W$43:$W$62='FC R12'!$B17), _xlpm.EOL, _xlfn.CHOOSECOLS(_xlpm.filtered,3), AVERAGE(_xlpm.EOL))} -> 2.1395772 | D17: {=_xlfn.LET(_xlpm.data, $W$43:$AB$62, _xlpm.filtered, _xlfn._xlws.FILTER(_xlpm.data, $W$43:$W$62='FC R12'!$B17), _xlpm.EOL, _xlfn.CHOOSECOLS(_xlpm.filtered,5), AVERAGE(_xlpm.EOL))} -> 2.7095397 | E17: {=_xlfn.LET(_xlpm.data, $W$43:$AB$62, _xlpm.filtered, _xlfn._xlws.FILTER(_xlpm.data, $W$43:$W$62='FC R12'!$B17), _xlpm.EOL, _xlfn.CHOOSECOLS(_xlpm.filtered,5), MAX(_xlpm.EOL))} -> 2.7879209 | G17: =D17*$C$4 -> 165.28192 | H17: =D17*$C$5 -> 4.0643096 | I17: =SUM(G17:H17) -> 169.34623 | J17: =I17-$C$6 -> 37.846233 | K17: =J17/$C$7 -> 1.5138493 | M17: =E17*$C$4 -> 170.06317 | N17: =E17*1.5 -> 4.1818814 | O17: =SUM(M17:N17) -> 174.24506 | P17: =O17-$C$6 -> 42.745056 | Q17: =P17/$C$7 -> 1.7098023 | AS17: Lap 5 | AT17: =#REF! -> #REF! | AU17: =#REF! -> #REF! | AV17: =#REF! -> #REF!
B18: Ford | C18: {=_xlfn.LET(_xlpm.data, $W$43:$AB$62, _xlpm.filtered, _xlfn._xlws.FILTER(_xlpm.data, $W$43:$W$62='FC R12'!$B18), _xlpm.EOL, _xlfn.CHOOSECOLS(_xlpm.filtered,3), AVERAGE(_xlpm.EOL))} -> 2.1655034 | D18: {=_xlfn.LET(_xlpm.data, $W$43:$AB$62, _xlpm.filtered, _xlfn._xlws.FILTER(_xlpm.data, $W$43:$W$62='FC R12'!$B18), _xlpm.EOL, _xlfn.CHOOSECOLS(_xlpm.filtered,5), AVERAGE(_xlpm.EOL))} -> 2.7423725 | E18: {=_xlfn.LET(_xlpm.data, $W$43:$AB$62, _xlpm.filtered, _xlfn._xlws.FILTER(_xlpm.data, $W$43:$W$62='FC R12'!$B18), _xlpm.EOL, _xlfn.CHOOSECOLS(_xlpm.filtered,5), MAX(_xlpm.EOL))} -> 2.7901557 | G18: =D18*$C$4 -> 167.28472 | H18: =D18*$C$5 -> 4.1135587 | I18: =SUM(G18:H18) -> 171.39828 | J18: =I18-$C$6 -> 39.898278 | K18: =J18/$C$7 -> 1.5959311 | M18: =E18*$C$4 -> 170.1995 | N18: =E18*1.5 -> 4.1852336 | O18: =SUM(M18:N18) -> 174.38473 | P18: =O18-$C$6 -> 42.884732 | Q18: =P18/$C$7 -> 1.7153893 | AS18: Lap 6 | AT18: =#REF! -> #REF! | AU18: =#REF! -> #REF! | AV18: =#REF! -> #REF!
B19: Toyota | C19: {=_xlfn.LET(_xlpm.data, $W$43:$AB$62, _xlpm.filtered, _xlfn._xlws.FILTER(_xlpm.data, $W$43:$W$62='FC R12'!$B19), _xlpm.EOL, _xlfn.CHOOSECOLS(_xlpm.filtered,3), AVERAGE(_xlpm.EOL))} -> 2.1879746 | D19: {=_xlfn.LET(_xlpm.data, $W$43:$AB$62, _xlpm.filtered, _xlfn._xlws.FILTER(_xlpm.data, $W$43:$W$62='FC R12'!$B19), _xlpm.EOL, _xlfn.CHOOSECOLS(_xlpm.filtered,5), AVERAGE(_xlpm.EOL))} -> 2.7708297 | E19: {=_xlfn.LET(_xlpm.data, $W$43:$AB$62, _xlpm.filtered, _xlfn._xlws.FILTER(_xlpm.data, $W$43:$W$62='FC R12'!$B19), _xlpm.EOL, _xlfn.CHOOSECOLS(_xlpm.filtered,5), MAX(_xlpm.EOL))} -> 2.8031921 | G19: =D19*$C$4 -> 169.02061 | H19: =D19*$C$5 -> 4.1562446 | I19: =SUM(G19:H19) -> 173.17686 | J19: =I19-$C$6 -> 41.676857 | K19: =J19/$C$7 -> 1.6670743 | M19: =E19*$C$4 -> 170.99472 | N19: =E19*1.5 -> 4.2047881 | O19: =SUM(M19:N19) -> 175.1995 | P19: =O19-$C$6 -> 43.699505 | Q19: =P19/$C$7 -> 1.7479802 | AS19: Lap 7 | AT19: =#REF! -> #REF! | AU19: =#REF! -> #REF! | AV19: =#REF! -> #REF!
B20: * Dash Calculates Fuel Used in Kg, Fuel Error is included in the number | AS20: Lap 8 | AT20: =#REF! -> #REF! | AU20: =#REF! -> #REF! | AV20: =#REF! -> #REF!
AS21: Lap 9 | AT21: =#REF! -> #REF! | AU21: =#REF! -> #REF! | AV21: =#REF! -> #REF!
G28: Average | M28: Max
B29: ECU | D29: Av Fuel Used [l] | E29: Max Fuel Used [l] | G29: Race Laps | H29: Out, F, In (1.5 Laps) | I29: Total Required | J29: Fuel Requied | K29: Churn Required | M29: Race Laps | N29: Out, F, In (1.5 Laps) | O29: Total Required | P29: Fuel Requied | Q29: Churn Required
